Workbook

Sheet Main Model
C1: Sahil Rajendra Kamble
A2: VARUN BEVERAGES
A3: Assumptions
B5: First year of forecast | D5: 2026 | K5: =$D$5 -> 2026 | L5: =K5+1 -> 2027 | M5: =L5+1 -> 2028 | N5: =M5+1 -> 2029 | O5: =N5+1 -> 2030
C6: Inflation Rate for Capex | D6: 0.05
B8: Scenarios & Sensitivity Analysis
B10: India Volume Growth % | D10: 1 | K10: =CHOOSE($D$10,K12,K13,K14) -> 0.11 | L10: =CHOOSE($D$10,L12,L13,L14) -> 0.1 | M10: =CHOOSE($D$10,M12,M13,M14) -> 0.1 | N10: =CHOOSE($D$10,N12,N13,N14) -> 0.1 | O10: =CHOOSE($D$10,O12,O13,O14) -> 0.1
B12: Base Case | K12: 0.11 | L12: 0.1 | M12: 0.1 | N12: 0.1 | O12: 0.1
B13: Best Case | K13: 0.14 | L13: 0.13 | M13: 0.13 | N13: 0.13 | O13: 0.13
B14: Worst Case | K14: 0.08 | L14: 0.08 | M14: 0.07 | N14: 0.07 | O14: 0.07
B16: International Volume Growth % | D16: 1 | K16: =CHOOSE($D$16,K18,K19,K20) -> 0.3 | L16: =CHOOSE($D$16,L18,L19,L20) -> 0.15 | M16: =CHOOSE($D$16,M18,M19,M20) -> 0.15 | N16: =CHOOSE($D$16,N18,N19,N20) -> 0.15 | O16: =CHOOSE($D$16,O18,O19,O20) -> 0.15
B18: Base Case | K18: 0.3 | L18: 0.15 | M18: 0.15 | N18: 0.15 | O18: 0.15
B19: Best Case | K19: 0.35 | L19: 0.2 | M19: 0.2 | N19: 0.2 | O19: 0.2
B20: Worst Case | K20: 0.25 | L20: 0.1 | M20: 0.1 | N20: 0.1 | O20: 0.1
B22: India realization per case Growth % | D22: 1 | K22: =CHOOSE($D$22,K24,K25,K26) -> 0.005 | L22: =CHOOSE($D$22,L24,L25,L26) -> 0.015 | M22: =CHOOSE($D$22,M24,M25,M26) -> 0.02 | N22: =CHOOSE($D$22,N24,N25,N26) -> 0.025 | O22: =CHOOSE($D$22,O24,O25,O26) -> 0.025
B24: Base Case | K24: 0.005 | L24: 0.015 | M24: 0.02 | N24: 0.025 | O24: 0.025
B25: Best Case | K25: 0.02 | L25: 0.03 | M25: 0.04 | N25: 0.04 | O25: 0.04
B26: Worst Case | K26: -0.015 | L26: -0.005 | M26: 0.005 | N26: 0.01 | O26: 0.01
B28: International realization per case Growth % | D28: 1 | K28: =CHOOSE($D$28,K30,K31,K32) -> 0.06 | L28: =CHOOSE($D$28,L30,L31,L32) -> 0.025 | M28: =CHOOSE($D$28,M30,M31,M32) -> 0.025 | N28: =CHOOSE($D$28,N30,N31,N32) -> 0.025 | O28: =CHOOSE($D$28,O30,O31,O32) -> 0.025
B30: Base Case | K30: 0.06 | L30: 0.025 | M30: 0.025 | N30: 0.025 | O30: 0.025
B31: Best Case | K31: 0.09 | L31: 0.045 | M31: 0.04 | N31: 0.04 | O31: 0.04
B32: Worst Case | K32: 0.01 | L32: 0 | M32: 0.01 | N32: 0.015 | O32: 0.015
B35: India Revenue
C36: Volume growth % | D36: (%) | K36: =K10 -> 0.11 | L36: =L10 -> 0.1 | M36: =M10 -> 0.1 | N36: =N10 -> 0.1 | O36: =O10 -> 0.1
C37: Realization per case growth % | D37: (%) | K37: =K22 -> 0.005 | L37: =L22 -> 0.015 | M37: =M22 -> 0.02 | N37: =N22 -> 0.025 | O37: =O22 -> 0.025
B39: International Revenue
C40: Volume growth rate | D40: (%) | K40: =K16 -> 0.3 | L40: =L16 -> 0.15 | M40: =M16 -> 0.15 | N40: =N16 -> 0.15 | O40: =O16 -> 0.15
C41: Realization per case growth % | D41: (%) | K41: =K28 -> 0.06 | L41: =L28 -> 0.025 | M41: =M28 -> 0.025 | N41: =N28 -> 0.025 | O41: =O28 -> 0.025
C42: Excise Duty % | D42: (%) | K42: =$J$246 -> 0.077229313 | L42: =$J$246 -> 0.077229313 | M42: =$J$246 -> 0.077229313 | N42: =$J$246 -> 0.077229313 | O42: =$J$246 -> 0.077229313
B45: Cost Schedule
C46: Margin for Cost of materials consumed | D46: (%) | K46: =$J$258 -> 0.44400923 | L46: =$J$258 -> 0.44400923 | M46: =$J$258 -> 0.44400923 | N46: =$J$258 -> 0.44400923 | O46: =$J$258 -> 0.44400923
C47: Other Expenses | D47: (%) | K47: =$J$263 -> 0.22556761 | L47: =$J$263 -> 0.22556761 | M47: =$J$263 -> 0.22556761 | N47: =$J$263 -> 0.22556761 | O47: =$J$263 -> 0.22556761
B50: Capex-Split Trend
C52: Land | E52: 0.02042
C53: Building + Plant & Equipment | E53: 0.81134
C54: Distribution & Others | E54: 0.16824
B56: Fixed Asset Schedule
C57: India Expansion Capex | K57: 5000 | L57: =K57*(1+$D$6) -> 5250 | M57: =L57*(1+$D$6) -> 5512.5 | N57: =M57*(1+$D$6) -> 5788.125 | O57: =N57*(1+$D$6) -> 6077.5312
C58: Total Maintenance Capex | J58: 10634.17 | K58: =J58*(1+$D$6) -> 11165.879 | L58: =K406 -> 13102.579 | M58: =L406 -> 14023.968 | N58: =M406 -> 15004.45 | O58: =N406 -> 16083.35
C59: Expansion Towards South Africa and CSD line in Kenya (CWIP) | K59: 4900
...

Sheet Term Loans
A3: Indian rupee loan from banks
B5: Term loan - 1
C7: Year | D7: Opening Balance | E7: Interest Rate | F7: Interest Payment | G7: Principal Repayment | H7: Closing Balance | L7: Period | M7: Days | N7: Balance | O7: Interest = Bal * IR *(days/365)
C8: 2026 | D8: 560.29 | E8: 0.0669 | F8: =SUM(O8:O10) -> 26.198269 | G8: 309.4 | H8: =D8-G8 -> 250.89 | L8: 1-Jan to 31-May26 | M8: 151 | N8: 560.29 | O8: =N8*$E$8*(M8/365) -> 15.506832
C9: 2027 | D9: =H8 -> 250.89 | E9: 0.0669 | F9: =SUM(O11:O12) -> 7.6335173 | G9: =250.89 -> 250.89 | H9: =D9-G9 -> 0 | L9: 1-June to 30-June26 | M9: 30 | N9: 405.59 | O9: =N9*$E$8*(M9/365) -> 2.2301894
L10: 1-July to 31-Dec26 | M10: 184 | N10: 250.89 | O10: =N10*$E$8*(M10/365) -> 8.4612481
L11: 1-Jan to 31-May27 | M11: 151 | N11: 250.89 | O11: =N11*$E$9*(M11/365) -> 6.9437416
L12: 1-June to 30-June27 | M12: 30 | N12: 125.445 | O12: =N12*$E$9*(M12/365) -> 0.68977566
B14: Term loan - 2
C16: Year | D16: Opening Balance | E16: Interest Rate | F16: Interest Payment | G16: Principal Repayment | H16: Closing Balnce | L16: Period | M16: Days | N16: Balance | O16: Interest = Bal * IR *(days/365)
C17: 2026 | D17: 282.64 | E17: 0.0669 | F17: =SUM(O17:O19) -> 13.754075 | G17: 141.32 | H17: =D17-G17 -> 141.32 | L17: 1-Jan to 31-May26 | M17: 151 | N17: 282.64 | O17: =N17*$E$17*(M17/365) -> 7.8224685
C18: 2027 | D18: =H17 -> 141.32 | E18: 0.0669 | F18: =SUM(O20:O21) -> 4.2997675 | G18: 141.32 | H18: =D18-G18 -> 0 | L18: 1-June to 30-June26 | M18: 30 | N18: 211.98 | O18: =N18*$E$17*(M18/365) -> 1.1655996
L19: 1-July to 31-Dec26 | M19: 184 | N19: 141.32 | O19: =N19*$E$17*(M19/365) -> 4.7660073
L20: 1-Jan to 31-May27 | M20: 151 | N20: 141.32 | O20: =N20*$E$18*(M20/365) -> 3.9112343
L21: 1-June to 30-June27 | M21: 30 | N21: 70.66 | O21: =N21*$E$18*(M21/365) -> 0.38853321
B23: Term loan - 4
C25: Year | D25: Opening Balance | E25: Interest Rate | F25: Interest Payment | G25: Principal Repayment | H25: Closing Balnce | L25: Period | M25: Days | N25: Balance | O25: Interest = Bal * IR *(days/365)
C26: 2026 | D26: 170.5 | E26: 0.0669 | F26: =SUM(O26:O28) -> 9.7257167 | G26: 46.08 | H26: =D26-G26 -> 124.42 | L26: 1-Jan to 31-May26 | M26: 151 | N26: 170.5 | O26: =N26*$E$26*(M26/365) -> 4.7188327
C27: 2027 | D27: =H26 -> 124.42 | E27: 0.0669 | F27: =SUM(O29:O31) -> 5.9703796 | G27: 64.52 | H27: =D27-G27 -> 59.9 | L27: 1-June to 30-June26 | M27: 30 | N27: 147.46 | O27: =N27*$E$26*(M27/365) -> 0.810828
C28: 2028 | D28: =H27 -> 59.9 | E28: 0.0669 | F28: =SUM(O32:O33) -> 1.8098008 | G28: 59.9 | H28: =D28-G28 -> 0 | L28: 1-July to 31-Dec26 | M28: 184 | N28: 124.42 | O28: =N28*$E$26*(M28/365) -> 4.196056
L29: 1-Jan to 31-May27 | M29: 151 | N29: 124.42 | O29: =N29*$E$27*(M29/365) -> 3.4435025
L30: 1-June to 30-June27 | M30: 30 | N30: 92.16 | O30: =N30*$E$27*(M30/365) -> 0.50675375
L31: 1-July to 31-Dec27 | M31: 184 | N31: 59.9 | O31: =N31*$E$27*(M31/365) -> 2.0201234
L32: 1-Jan to 31-May28 | M32: 151 | N32: 59.9 | O32: =N32*$E$28*(M32/365) -> 1.6578187
L33: 1-June to 30-June28 | M33: 30 | N33: 27.64 | O33: =N33*$E$28*(M33/365) -> 0.15198214
B35: Term loan - 5
C37: Year | D37: Opening Balance | E37: Interest Rate | F37: Interest Payment | G37: Principal Repayment | H37: Closing Balance | L37: Period | M37: Days | N37: Balance | O37: Interest = Bal * IR *(days/365)
C38: 2026 | D38: 2400 | E38: 0.0669 | F38: =SUM(O38:O40) -> 138.67545 | G38: 600 | H38: =D38-G38 -> 1800 | L38: 1-Jan to 31-May26 | M38: 151 | N38: 2400 | O38: =N38*$E$38*(M38/365) -> 66.423452
C39: 2027 | D39: =H38 -> 1800 | E39: 0.0669 | F39: =SUM(O41:O43) -> 98.535452 | G39: 600 | H39: =D39-G39 -> 1200 | L39: 1-June to 30-June26 | M39: 30 | N39: 2100 | O39: =N39*$E$38*(M39/365) -> 11.547123
C40: 2028 | D40: =H39 -> 1200 | E40: 0.0669 | F40: =SUM(O44:O46) -> 58.395452 | G40: 600 | H40: =D40-G40 -> 600 | L40: 1-July to 31-Dec26 | M40: 184 | N40: 1800 | O40: =N40*$E$38*(M40/365) -> 60.704877
C41: 2029 | D41: =H40 -> 600 | E41: 0.0669 | F41: =SUM(O47:O48) -> 18.255452 | G41: 600 | H41: =D41-G41 -> 0 | L41: 1-Jan to 31-May27 | M41: 151 | N41: 1800 | O41: =N41*$E$39*(M41/365) -> 49.817589
L42: 1-June to 30-June27 | M42: 30 | N42: 1500 | O42: =N42*$E$39*(M42/365) -> 8.2479452
L43: 1-July to 31-Dec27 | M43: 184 | N43: 1200 | O43: =N43*$E$39*(M43/365) -> 40.469918
L44: 1-Jan to 31-May28 | M44: 151 | N44: 1200 | O44: =N44*$E$40*(M44/365) -> 33.211726
L45: 1-June to 30-June28 | M45: 30 | N45: 900 | O45: =N45*$E$40*(M45/365) -> 4.9487671
L46: 1-July to 31-Dec27 | M46: 184 | N46: 600 | O46: =N46*$E$40*(M46/365) -> 20.234959
L47: 1-Jan to 31-May28 | M47: 151 | N47: 600 | O47: =N47*$E$41*(M47/365) -> 16.605863
L48: 1-June to 30-June28 | M48: 30 | N48: 300 | O48: =N48*$E$41*(M48/365) -> 1.649589
B50: Total
C51: Year | D51: Opening Balance | E51: Interest Paid | F51: Principal Paid | G51: Closing Balance
...

Sheet Spare
A2: VARUN BEVERAGES
A3: Assumptions
B5: First year of forecast | D5: 2026 | K5: =$D$5 -> 2026 | L5: =K5+1 -> 2027 | M5: =L5+1 -> 2028 | N5: =M5+1 -> 2029 | O5: =N5+1 -> 2030
C6: Inflation Rate for Capex | D6: 0.05
B8: Scenarios
B10: India Volume Growth % | D10: 1 | K10: =CHOOSE($D$10,K12,K13,K14) -> 0.11 | L10: =CHOOSE($D$10,L12,L13,L14) -> 0.1 | M10: =CHOOSE($D$10,M12,M13,M14) -> 0.09 | N10: =CHOOSE($D$10,N12,N13,N14) -> 0.08 | O10: =CHOOSE($D$10,O12,O13,O14) -> 0.07
B12: Base Case | K12: 0.11 | L12: 0.1 | M12: 0.09 | N12: 0.08 | O12: 0.07
B13: Best Case | K13: 0.14 | L13: 0.13 | M13: 0.13 | N13: 0.13 | O13: 0.13
B14: Worst Case | K14: 0.08 | L14: 0.08 | M14: 0.07 | N14: 0.06 | O14: 0.05
B16: International Volume Growth % | D16: 1 | K16: =CHOOSE($D$16,K18,K19,K20) -> 0.3 | L16: =CHOOSE($D$16,L18,L19,L20) -> 0.15 | M16: =CHOOSE($D$16,M18,M19,M20) -> 0.14 | N16: =CHOOSE($D$16,N18,N19,N20) -> 0.13 | O16: =CHOOSE($D$16,O18,O19,O20) -> 0.12
B18: Base Case | K18: 0.3 | L18: 0.15 | M18: 0.14 | N18: 0.13 | O18: 0.12
B19: Best Case | K19: 0.34 | L19: 0.17 | M19: 0.16 | N19: 0.15 | O19: 0.14
B20: Worst Case | K20: 0.24 | L20: 0.1 | M20: 0.1 | N20: 0.1 | O20: 0.1
B22: India realization per case Growth % | D22: 1 | K22: =CHOOSE($D$22,K24,K25,K26) -> 0.005 | L22: =CHOOSE($D$22,L24,L25,L26) -> 0.015 | M22: =CHOOSE($D$22,M24,M25,M26) -> 0.02 | N22: =CHOOSE($D$22,N24,N25,N26) -> 0.025 | O22: =CHOOSE($D$22,O24,O25,O26) -> 0.025
B24: Base Case | K24: 0.005 | L24: 0.015 | M24: 0.02 | N24: 0.025 | O24: 0.025
B25: Best Case | K25: 0.02 | L25: 0.03 | M25: 0.04 | N25: 0.04 | O25: 0.04
B26: Worst Case | K26: -0.015 | L26: -0.005 | M26: 0.005 | N26: 0.01 | O26: 0.01
B28: International realization per case Growth % | D28: 1 | K28: =CHOOSE($D$28,K30,K31,K32) -> 0.06 | L28: =CHOOSE($D$28,L30,L31,L32) -> 0.025 | M28: =CHOOSE($D$28,M30,M31,M32) -> 0.025 | N28: =CHOOSE($D$28,N30,N31,N32) -> 0.025 | O28: =CHOOSE($D$28,O30,O31,O32) -> 0.025
B30: Base Case | K30: 0.06 | L30: 0.025 | M30: 0.025 | N30: 0.025 | O30: 0.025
B31: Best Case | K31: 0.09 | L31: 0.045 | M31: 0.04 | N31: 0.04 | O31: 0.04
B32: Worst Case | K32: 0.01 | L32: 0 | M32: 0.01 | N32: 0.015 | O32: 0.015
B35: India Revenue
C36: Volume growth % | D36: (%) | K36: =K10 -> 0.11 | L36: =L10 -> 0.1 | M36: =M10 -> 0.09 | N36: =N10 -> 0.08 | O36: =O10 -> 0.07
C37: Realization per case growth % | D37: (%) | K37: =K22 -> 0.005 | L37: =L22 -> 0.015 | M37: =M22 -> 0.02 | N37: =N22 -> 0.025 | O37: =O22 -> 0.025
B39: International Revenue
C40: Volume growth rate | D40: (%) | K40: =K16 -> 0.3 | L40: =L16 -> 0.15 | M40: =M16 -> 0.14 | N40: =N16 -> 0.13 | O40: =O16 -> 0.12
C41: Realization per case growth % | D41: (%) | K41: =K28 -> 0.06 | L41: =L28 -> 0.025 | M41: =M28 -> 0.025 | N41: =N28 -> 0.025 | O41: =O28 -> 0.025
C42: Excise Duty % | D42: (%) | K42: =$J$246 -> 0.077229313 | L42: =$J$246 -> 0.077229313 | M42: =$J$246 -> 0.077229313 | N42: =$J$246 -> 0.077229313 | O42: =$J$246 -> 0.077229313
B45: Cost Schedule
C46: Margin for Cost of materials consumed | D46: (%) | K46: =$J$258 -> 0.44400923 | L46: =$J$258 -> 0.44400923 | M46: =$J$258 -> 0.44400923 | N46: =$J$258 -> 0.44400923 | O46: =$J$258 -> 0.44400923
C47: Other Expenses | D47: (%) | K47: =$J$263 -> 0.22556761 | L47: =$J$263 -> 0.22556761 | M47: =$J$263 -> 0.22556761 | N47: =$J$263 -> 0.22556761 | O47: =$J$263 -> 0.22556761
B50: Capex-Split Trend
C52: Land | E52: 0.02042
C53: Building + Plant & Equipment | E53: 0.81134
C54: Distribution & Others | E54: 0.16824
B56: Fixed Asset Schedule
C57: India Expansion Capex | K57: 5000 | L57: =K57*(1+$D$6) -> 5250 | M57: =L57*(1+$D$6) -> 5512.5 | N57: =M57*(1+$D$6) -> 5788.125 | O57: =N57*(1+$D$6) -> 6077.5312
C58: Total Maintenance Capex | J58: 10634.17 | K58: =J58*(1+$D$6) -> 11165.879 | L58: =K406 -> 13102.579 | M58: =L406 -> 14023.968 | N58: =M406 -> 15004.45 | O58: =N406 -> 16083.35
C59: Expansion Towards South Africa and CSD line in Kenya (CWIP) | K59: 4900
C60: CWIP Transfer to PPE
...

Sheet Sheet1
